Workbook
Name ARE: #REF!
Name CCDebt: #REF!
Name CCDebtM: #REF!
Name CCDebtP: #REF!
Name CCDebtR: #REF!
Name CoH: #REF!
Name CommLoan: #REF!
Name CommLoanM: #REF!
Name CommLoanP: #REF!
Name CommLoanR: #REF!
Name DR: #REF!
Name ED: #REF!
Name IDC: #REF!
Name LI: #REF!
Name LL: #REF!
Name LPP: #REF!
Name LT: #REF!
Name LTC: #REF!
Name LTPC: #REF!
Name MPA: #REF!
Name NetIncY1: #REF!
Name NetIncY2: #REF!
Name NetIncY3: #REF!
Name OutsideInvestors: #REF!
Name OwnerEquity: #REF!
Name PPIns: #REF!
Name ROUA: #REF!
Name SD: #REF!
Name SUSect195Amor: #REF!
Name SUSect195Total: #REF!
Name SUTotalOrg: #REF!
Name SUTotalReqFunds: #REF!
Name SUTotalSourcesFunds: #REF!
Name TPA: #REF!
Name TSLE: #REF!
Name Y1EndingCashBal: #REF!
Name Y2EndingCashBal: #REF!
Name Y3EndingCashBal: #REF!

Sheet ForeMonth
A1: Month | B1: Year | C1: Room | D1: Available | E1: UsedHrs | F1: UnusedHrs | G1: % Used | H1: BusYr | I1: BusMnth
A2: 4 | B2: 2026 | C2: 1 | D2: =SUMIFS(Calendar!$F$1:$F$9997,Calendar!$B$1:$B$9997,ForeMonth!B2,Calendar!$C$1:$C$9997,ForeMonth!A2) | E2: =ROUND(SUMIFS(ForeDaily!F:F,ForeDaily!C:C,A2,ForeDaily!D:D,B2,ForeDaily!E:E,C2),0) | F2: =D2-E2 | G2: =E2/D2 | H2: 1 | I2: 1
A3: 5 | B3: 2026 | C3: 1 | D3: =SUMIFS(Calendar!$F$1:$F$9997,Calendar!$B$1:$B$9997,ForeMonth!B3,Calendar!$C$1:$C$9997,ForeMonth!A3) | E3: =ROUND(SUMIFS(ForeDaily!F:F,ForeDaily!C:C,A3,ForeDaily!D:D,B3,ForeDaily!E:E,C3),0) | F3: =D3-E3 | G3: =E3/D3 | H3: 1 | I3: 2
A4: 6 | B4: 2026 | C4: 1 | D4: =SUMIFS(Calendar!$F$1:$F$9997,Calendar!$B$1:$B$9997,ForeMonth!B4,Calendar!$C$1:$C$9997,ForeMonth!A4) | E4: =ROUND(SUMIFS(ForeDaily!F:F,ForeDaily!C:C,A4,ForeDaily!D:D,B4,ForeDaily!E:E,C4),0) | F4: =D4-E4 | G4: =E4/D4 | H4: 1 | I4: 3
A5: 7 | B5: 2026 | C5: 1 | D5: =SUMIFS(Calendar!$F$1:$F$9997,Calendar!$B$1:$B$9997,ForeMonth!B5,Calendar!$C$1:$C$9997,ForeMonth!A5) | E5: =ROUND(SUMIFS(ForeDaily!F:F,ForeDaily!C:C,A5,ForeDaily!D:D,B5,ForeDaily!E:E,C5),0) | F5: =D5-E5 | G5: =E5/D5 | H5: 1 | I5: 4
A6: 8 | B6: 2026 | C6: 1 | D6: =SUMIFS(Calendar!$F$1:$F$9997,Calendar!$B$1:$B$9997,ForeMonth!B6,Calendar!$C$1:$C$9997,ForeMonth!A6) | E6: =ROUND(SUMIFS(ForeDaily!F:F,ForeDaily!C:C,A6,ForeDaily!D:D,B6,ForeDaily!E:E,C6),0) | F6: =D6-E6 | G6: =E6/D6 | H6: 1 | I6: 5
A7: 9 | B7: 2026 | C7: 1 | D7: =SUMIFS(Calendar!$F$1:$F$9997,Calendar!$B$1:$B$9997,ForeMonth!B7,Calendar!$C$1:$C$9997,ForeMonth!A7) | E7: =ROUND(SUMIFS(ForeDaily!F:F,ForeDaily!C:C,A7,ForeDaily!D:D,B7,ForeDaily!E:E,C7),0) | F7: =D7-E7 | G7: =E7/D7 | H7: 1 | I7: 6
A8: 10 | B8: 2026 | C8: 1 | D8: =SUMIFS(Calendar!$F$1:$F$9997,Calendar!$B$1:$B$9997,ForeMonth!B8,Calendar!$C$1:$C$9997,ForeMonth!A8) | E8: =ROUND(SUMIFS(ForeDaily!F:F,ForeDaily!C:C,A8,ForeDaily!D:D,B8,ForeDaily!E:E,C8),0) | F8: =D8-E8 | G8: =E8/D8 | H8: 1 | I8: 7
A9: 11 | B9: 2026 | C9: 1 | D9: =SUMIFS(Calendar!$F$1:$F$9997,Calendar!$B$1:$B$9997,ForeMonth!B9,Calendar!$C$1:$C$9997,ForeMonth!A9) | E9: =ROUND(SUMIFS(ForeDaily!F:F,ForeDaily!C:C,A9,ForeDaily!D:D,B9,ForeDaily!E:E,C9),0) | F9: =D9-E9 | G9: =E9/D9 | H9: 1 | I9: 8
A10: 12 | B10: 2026 | C10: 1 | D10: =SUMIFS(Calendar!$F$1:$F$9997,Calendar!$B$1:$B$9997,ForeMonth!B10,Calendar!$C$1:$C$9997,ForeMonth!A10) | E10: =ROUND(SUMIFS(ForeDaily!F:F,ForeDaily!C:C,A10,ForeDaily!D:D,B10,ForeDaily!E:E,C10),0) | F10: =D10-E10 | G10: =E10/D10 | H10: 1 | I10: 9
A11: 1 | B11: 2027 | C11: 1 | D11: =SUMIFS(Calendar!$F$1:$F$9997,Calendar!$B$1:$B$9997,ForeMonth!B11,Calendar!$C$1:$C$9997,ForeMonth!A11) | E11: =ROUND(SUMIFS(ForeDaily!F:F,ForeDaily!C:C,A11,ForeDaily!D:D,B11,ForeDaily!E:E,C11),0) | F11: =D11-E11 | G11: =E11/D11 | H11: 1 | I11: 10
A12: 2 | B12: 2027 | C12: 1 | D12: =SUMIFS(Calendar!$F$1:$F$9997,Calendar!$B$1:$B$9997,ForeMonth!B12,Calendar!$C$1:$C$9997,ForeMonth!A12) | E12: =ROUND(SUMIFS(ForeDaily!F:F,ForeDaily!C:C,A12,ForeDaily!D:D,B12,ForeDaily!E:E,C12),0) | F12: =D12-E12 | G12: =E12/D12 | H12: 1 | I12: 11
A13: 3 | B13: 2027 | C13: 1 | D13: =SUMIFS(Calendar!$F$1:$F$9997,Calendar!$B$1:$B$9997,ForeMonth!B13,Calendar!$C$1:$C$9997,ForeMonth!A13) | E13: =ROUND(SUMIFS(ForeDaily!F:F,ForeDaily!C:C,A13,ForeDaily!D:D,B13,ForeDaily!E:E,C13),0) | F13: =D13-E13 | G13: =E13/D13 | H13: 1 | I13: 12
... A289: 3 | B289: 2029 | C289: 8 | D289: =SUMIFS(Calendar!$F$1:$F$9997,Calendar!$B$1:$B$9997,ForeMonth!B289,Calendar!$C$1:$C$9997,ForeMonth!A289) | E289: =ROUND(SUMIFS(ForeDaily!F:F,ForeDaily!C:C,A289,ForeDaily!D:D,B289,ForeDaily!E:E,C289),0) | F289: =D289-E289 | G289: =E289/D289 | H289: 3 | I289: 12

Sheet ForeDaily
A1: Date | B1: Day | C1: Month | D1: Year | E1: Room | F1: UsedHrs | G1: UnusedHrs | H1: BusYr | I1: BusMnth
A2: 46113 | B2: Week | C2: 4 | D2: 2026 | E2: 1 | F2: =ROUND(((SUMIFS(Calendar!$F$2:$F$9997,Calendar!$B$2:$B$9997,D2,Calendar!$C$2:$C$9997,C2)*INDEX(ForeCalc!$B$37:$Y$274,MATCH(_xlfn.CONCAT(H2," ",I2),ForeCalc!$A$37:$A$274,0),MATCH(_xlfn.CONCAT(B2," ",E2),ForeCalc!$B$36:$Y$36,0))))*VLOOKUP(A2,Calendar!$A$2:$H$9997,8,FALSE),0) | G2: =VLOOKUP(A2,Calendar!$A$1:$H$9997,6,FALSE)-F2 | H2: 1 | I2: 1
A3: 46114 | B3: Week | C3: 4 | D3: 2026 | E3: 1 | F3: =ROUND(((SUMIFS(Calendar!$F$2:$F$9997,Calendar!$B$2:$B$9997,D3,Calendar!$C$2:$C$9997,C3)*INDEX(ForeCalc!$B$37:$Y$274,MATCH(_xlfn.CONCAT(H3," ",I3),ForeCalc!$A$37:$A$274,0),MATCH(_xlfn.CONCAT(B3," ",E3),ForeCalc!$B$36:$Y$36,0))))*VLOOKUP(A3,Calendar!$A$2:$H$9997,8,FALSE),0) | G3: =VLOOKUP(A3,Calendar!$A$1:$H$9997,6,FALSE)-F3 | H3: 1 | I3: 1
A4: 46115 | B4: Week | C4: 4 | D4: 2026 | E4: 1 | F4: =ROUND(((SUMIFS(Calendar!$F$2:$F$9997,Calendar!$B$2:$B$9997,D4,Calendar!$C$2:$C$9997,C4)*INDEX(ForeCalc!$B$37:$Y$274,MATCH(_xlfn.CONCAT(H4," ",I4),ForeCalc!$A$37:$A$274,0),MATCH(_xlfn.CONCAT(B4," ",E4),ForeCalc!$B$36:$Y$36,0))))*VLOOKUP(A4,Calendar!$A$2:$H$9997,8,FALSE),0) | G4: =VLOOKUP(A4,Calendar!$A$1:$H$9997,6,FALSE)-F4 | H4: 1 | I4: 1
A5: 46116 | B5: Sat | C5: 4 | D5: 2026 | E5: 1 | F5: =ROUND(((SUMIFS(Calendar!$F$2:$F$9997,Calendar!$B$2:$B$9997,D5,Calendar!$C$2:$C$9997,C5)*INDEX(ForeCalc!$B$37:$Y$274,MATCH(_xlfn.CONCAT(H5," ",I5),ForeCalc!$A$37:$A$274,0),MATCH(_xlfn.CONCAT(B5," ",E5),ForeCalc!$B$36:$Y$36,0))))*VLOOKUP(A5,Calendar!$A$2:$H$9997,8,FALSE),0) | G5: =VLOOKUP(A5,Calendar!$A$1:$H$9997,6,FALSE)-F5 | H5: 1 | I5: 1
A6: 46117 | B6: Sun | C6: 4 | D6: 2026 | E6: 1 | F6: =ROUND(((SUMIFS(Calendar!$F$2:$F$9997,Calendar!$B$2:$B$9997,D6,Calendar!$C$2:$C$9997,C6)*INDEX(ForeCalc!$B$37:$Y$274,MATCH(_xlfn.CONCAT(H6," ",I6),ForeCalc!$A$37:$A$274,0),MATCH(_xlfn.CONCAT(B6," ",E6),ForeCalc!$B$36:$Y$36,0))))*VLOOKUP(A6,Calendar!$A$2:$H$9997,8,FALSE),0) | G6: =VLOOKUP(A6,Calendar!$A$1:$H$9997,6,FALSE)-F6 | H6: 1 | I6: 1
A7: 46118 | B7: Week | C7: 4 | D7: 2026 | E7: 1 | F7: =ROUND(((SUMIFS(Calendar!$F$2:$F$9997,Calendar!$B$2:$B$9997,D7,Calendar!$C$2:$C$9997,C7)*INDEX(ForeCalc!$B$37:$Y$274,MATCH(_xlfn.CONCAT(H7," ",I7),ForeCalc!$A$37:$A$274,0),MATCH(_xlfn.CONCAT(B7," ",E7),ForeCalc!$B$36:$Y$36,0))))*VLOOKUP(A7,Calendar!$A$2:$H$9997,8,FALSE),0) | G7: =VLOOKUP(A7,Calendar!$A$1:$H$9997,6,FALSE)-F7 | H7: 1 | I7: 1
A8: 46119 | B8: Week | C8: 4 | D8: 2026 | E8: 1 | F8: =ROUND(((SUMIFS(Calendar!$F$2:$F$9997,Calendar!$B$2:$B$9997,D8,Calendar!$C$2:$C$9997,C8)*INDEX(ForeCalc!$B$37:$Y$274,MATCH(_xlfn.CONCAT(H8," ",I8),ForeCalc!$A$37:$A$274,0),MATCH(_xlfn.CONCAT(B8," ",E8),ForeCalc!$B$36:$Y$36,0))))*VLOOKUP(A8,Calendar!$A$2:$H$9997,8,FALSE),0) | G8: =VLOOKUP(A8,Calendar!$A$1:$H$9997,6,FALSE)-F8 | H8: 1 | I8: 1
A9: 46120 | B9: Week | C9: 4 | D9: 2026 | E9: 1 | F9: =ROUND(((SUMIFS(Calendar!$F$2:$F$9997,Calendar!$B$2:$B$9997,D9,Calendar!$C$2:$C$9997,C9)*INDEX(ForeCalc!$B$37:$Y$274,MATCH(_xlfn.CONCAT(H9," ",I9),ForeCalc!$A$37:$A$274,0),MATCH(_xlfn.CONCAT(B9," ",E9),ForeCalc!$B$36:$Y$36,0))))*VLOOKUP(A9,Calendar!$A$2:$H$9997,8,FALSE),0) | G9: =VLOOKUP(A9,Calendar!$A$1:$H$9997,6,FALSE)-F9 | H9: 1 | I9: 1
A10: 46121 | B10: Week | C10: 4 | D10: 2026 | E10: 1 | F10: =ROUND(((SUMIFS(Calendar!$F$2:$F$9997,Calendar!$B$2:$B$9997,D10,Calendar!$C$2:$C$9997,C10)*INDEX(ForeCalc!$B$37:$Y$274,MATCH(_xlfn.CONCAT(H10," ",I10),ForeCalc!$A$37:$A$274,0),MATCH(_xlfn.CONCAT(B10," ",E10),ForeCalc!$B$36:$Y$36,0))))*VLOOKUP(A10,Calendar!$A$2:$H$9997,8,FALSE),0) | G10: =VLOOKUP(A10,Calendar!$A$1:$H$9997,6,FALSE)-F10 | H10: 1 | I10: 1
A11: 46122 | B11: Week | C11: 4 | D11: 2026 | E11: 1 | F11: =ROUND(((SUMIFS(Calendar!$F$2:$F$9997,Calendar!$B$2:$B$9997,D11,Calendar!$C$2:$C$9997,C11)*INDEX(ForeCalc!$B$37:$Y$274,MATCH(_xlfn.CONCAT(H11," ",I11),ForeCalc!$A$37:$A$274,0),MATCH(_xlfn.CONCAT(B11," ",E11),ForeCalc!$B$36:$Y$36,0))))*VLOOKUP(A11,Calendar!$A$2:$H$9997,8,FALSE),0) | G11: =VLOOKUP(A11,Calendar!$A$1:$H$9997,6,FALSE)-F11 | H11: 1 | I11: 1
A12: 46123 | B12: Sat | C12: 4 | D12: 2026 | E12: 1 | F12: =ROUND(((SUMIFS(Calendar!$F$2:$F$9997,Calendar!$B$2:$B$9997,D12,Calendar!$C$2:$C$9997,C12)*INDEX(ForeCalc!$B$37:$Y$274,MATCH(_xlfn.CONCAT(H12," ",I12),ForeCalc!$A$37:$A$274,0),MATCH(_xlfn.CONCAT(B12," ",E12),ForeCalc!$B$36:$Y$36,0))))*VLOOKUP(A12,Calendar!$A$2:$H$9997,8,FALSE),0) | G12: =VLOOKUP(A12,Calendar!$A$1:$H$9997,6,FALSE)-F12 | H12: 1 | I12: 1
A13: 46124 | B13: Sun | C13: 4 | D13: 2026 | E13: 1 | F13: =ROUND(((SUMIFS(Calendar!$F$2:$F$9997,Calendar!$B$2:$B$9997,D13,Calendar!$C$2:$C$9997,C13)*INDEX(ForeCalc!$B$37:$Y$274,MATCH(_xlfn.CONCAT(H13," ",I13),ForeCalc!$A$37:$A$274,0),MATCH(_xlfn.CONCAT(B13," ",E13),ForeCalc!$B$36:$Y$36,0))))*VLOOKUP(A13,Calendar!$A$2:$H$9997,8,FALSE),0) | G13: =VLOOKUP(A13,Calendar!$A$1:$H$9997,6,FALSE)-F13 | H13: 1 | I13: 1
... A8033: 46472 | B8033: Week | C8033: 3 | D8033: 2027 | E8033: 8 | F8033: =ROUND(((SUMIFS(Calendar!$F$2:$F$9997,Calendar!$B$2:$B$9997,D8033,Calendar!$C$2:$C$9997,C8033)*INDEX(ForeCalc!$B$37:$Y$274,MATCH(_xlfn.CONCAT(H8033," ",I8033),ForeCalc!$A$37:$A$274,0),MATCH(_xlfn.CONCAT(B8033," ",E8033),ForeCalc!$B$36:$Y$36,0))))*VLOOKUP(A8033,Calendar!$A$2:$H$9997,8,FALSE),0) | G8033: =VLOOKUP(A8033,Calendar!$A$1:$H$9997,6,FALSE)-F8033 | H8033: 1 | I8033: 12
A8034: 46473 | B8034: Sat | C8034: 3 | D8034: 2027 | E8034: 8 | F8034: =ROUND(((SUMIFS(Calendar!$F$2:$F$9997,Calendar!$B$2:$B$9997,D8034,Calendar!$C$2:$C$9997,C8034)*INDEX(ForeCalc!$B$37:$Y$274,MATCH(_xlfn.CONCAT(H8034," ",I8034),ForeCalc!$A$37:$A$274,0),MATCH(_xlfn.CONCAT(B8034," ",E8034),ForeCalc!$B$36:$Y$36,0))))*VLOOKUP(A8034,Calendar!$A$2:$H$9997,8,FALSE),0) | G8034: =VLOOKUP(A8034,Calendar!$A$1:$H$9997,6,FALSE)-F8034 | H8034: 1 | I8034: 12 | L8034: =SUMIFS(Calendar!$F$2:$F$9997,Calendar!$B$2:$B$9997,D8034,Calendar!$C$2:$C$9997,C8034)
A8035: 46474 | B8035: Sun | C8035: 3 | D8035: 2027 | E8035: 8 | F8035: =ROUND(((SUMIFS(Calendar!$F$2:$F$9997,Calendar!$B$2:$B$9997,D8035,Calendar!$C$2:$C$9997,C8035)*INDEX(ForeCalc!$B$37:$Y$274,MATCH(_xlfn.CONCAT(H8035," ",I8035),ForeCalc!$A$37:$A$274,0),MATCH(_xlfn.CONCAT(B8035," ",E8035),ForeCalc!$B$36:$Y$36,0))))*VLOOKUP(A8035,Calendar!$A$2:$H$9997,8,FALSE),0) | G8035: =VLOOKUP(A8035,Calendar!$A$1:$H$9997,6,FALSE)-F8035 | H8035: 1 | I8035: 12
A8036: 46475 | B8036: Week | C8036: 3 | D8036: 2027 | E8036: 8 | F8036: =ROUND(((SUMIFS(Calendar!$F$2:$F$9997,Calendar!$B$2:$B$9997,D8036,Calendar!$C$2:$C$9997,C8036)*INDEX(ForeCalc!$B$37:$Y$274,MATCH(_xlfn.CONCAT(H8036," ",I8036),ForeCalc!$A$37:$A$274,0),MATCH(_xlfn.CONCAT(B8036," ",E8036),ForeCalc!$B$36:$Y$36,0))))*VLOOKUP(A8036,Calendar!$A$2:$H$9997,8,FALSE),0) | G8036: =VLOOKUP(A8036,Calendar!$A$1:$H$9997,6,FALSE)-F8036 | H8036: 1 | I8036: 12
A8037: 46476 | B8037: Week | C8037: 3 | D8037: 2027 | E8037: 8 | F8037: =ROUND(((SUMIFS(Calendar!$F$2:$F$9997,Calendar!$B$2:$B$9997,D8037,Calendar!$C$2:$C$9997,C8037)*INDEX(ForeCalc!$B$37:$Y$274,MATCH(_xlfn.CONCAT(H8037," ",I8037),ForeCalc!$A$37:$A$274,0),MATCH(_xlfn.CONCAT(B8037," ",E8037),ForeCalc!$B$36:$Y$36,0))))*VLOOKUP(A8037,Calendar!$A$2:$H$9997,8,FALSE),0) | G8037: =VLOOKUP(A8037,Calendar!$A$1:$H$9997,6,FALSE)-F8037 | H8037: 1 | I8037: 12
A8038: 46477 | B8038: Week | C8038: 3 | D8038: 2027 | E8038: 8 | F8038: =ROUND(((SUMIFS(Calendar!$F$2:$F$9997,Calendar!$B$2:$B$9997,D8038,Calendar!$C$2:$C$9997,C8038)*INDEX(ForeCalc!$B$37:$Y$274,MATCH(_xlfn.CONCAT(H8038," ",I8038),ForeCalc!$A$37:$A$274,0),MATCH(_xlfn.CONCAT(B8038," ",E8038),ForeCalc!$B$36:$Y$36,0))))*VLOOKUP(A8038,Calendar!$A$2:$H$9997,8,FALSE),0) | G8038: =VLOOKUP(A8038,Calendar!$A$1:$H$9997,6,FALSE)-F8038 | H8038: 1 | I8038: 12
A8039: 46478 | B8039: Week | C8039: 4 | D8039: 2027 | E8039: 8 | F8039: =ROUND(((SUMIFS(Calendar!$F$2:$F$9997,Calendar!$B$2:$B$9997,D8039,Calendar!$C$2:$C$9997,C8039)*INDEX(ForeCalc!$B$37:$Y$274,MATCH(_xlfn.CONCAT(H8039," ",I8039),ForeCalc!$A$37:$A$274,0),MATCH(_xlfn.CONCAT(B8039," ",E8039),ForeCalc!$B$36:$Y$36,0))))*VLOOKUP(A8039,Calendar!$A$2:$H$9997,8,FALSE),0) | G8039: =VLOOKUP(A8039,Calendar!$A$1:$H$9997,6,FALSE)-F8039 | H8039: 2 | I8039: 1
A8040: 46479 | B8040: Week | C8040: 4 | D8040: 2027 | E8040: 8 | F8040: =ROUND(((SUMIFS(Calendar!$F$2:$F$9997,Calendar!$B$2:$B$9997,D8040,Calendar!$C$2:$C$9997,C8040)*INDEX(ForeCalc!$B$37:$Y$274,MATCH(_xlfn.CONCAT(H8040," ",I8040),ForeCalc!$A$37:$A$274,0),MATCH(_xlfn.CONCAT(B8040," ",E8040),ForeCalc!$B$36:$Y$36,0))))*VLOOKUP(A8040,Calendar!$A$2:$H$9997,8,FALSE),0) | G8040: =VLOOKUP(A8040,Calendar!$A$1:$H$9997,6,FALSE)-F8040 | H8040: 2 | I8040: 1
A8041: 46480 | B8041: Sat | C8041: 4 | D8041: 2027 | E8041: 8 | F8041: =ROUND(((SUMIFS(Calendar!$F$2:$F$9997,Calendar!$B$2:$B$9997,D8041,Calendar!$C$2:$C$9997,C8041)*INDEX(ForeCalc!$B$37:$Y$274,MATCH(_xlfn.CONCAT(H8041," ",I8041),ForeCalc!$A$37:$A$274,0),MATCH(_xlfn.CONCAT(B8041," ",E8041),ForeCalc!$B$36:$Y$36,0))))*VLOOKUP(A8041,Calendar!$A$2:$H$9997,8,FALSE),0) | G8041: =VLOOKUP(A8041,Calendar!$A$1:$H$9997,6,FALSE)-F8041 | H8041: 2 | I8041: 1
A8042: 46481 | B8042: Sun | C8042: 4 | D8042: 2027 | E8042: 8 | F8042: =ROUND(((SUMIFS(Calendar!$F$2:$F$9997,Calendar!$B$2:$B$9997,D8042,Calendar!$C$2:$C$9997,C8042)*INDEX(ForeCalc!$B$37:$Y$274,MATCH(_xlfn.CONCAT(H8042," ",I8042),ForeCalc!$A$37:$A$274,0),MATCH(_xlfn.CONCAT(B8042," ",E8042),ForeCalc!$B$36:$Y$36,0))))*VLOOKUP(A8042,Calendar!$A$2:$H$9997,8,FALSE),0) | G8042: =VLOOKUP(A8042,Calendar!$A$1:$H$9997,6,FALSE)-F8042 | H8042: 2 | I8042: 1
A8043: 46482 | B8043: Week | C8043: 4 | D8043: 2027 | E8043: 8 | F8043: =ROUND(((SUMIFS(Calendar!$F$2:$F$9997,Calendar!$B$2:$B$9997,D8043,Calendar!$C$2:$C$9997,C8043)*INDEX(ForeCalc!$B$37:$Y$274,MATCH(_xlfn.CONCAT(H8043," ",I8043),ForeCalc!$A$37:$A$274,0),MATCH(_xlfn.CONCAT(B8043," ",E8043),ForeCalc!$B$36:$Y$36,0))))*VLOOKUP(A8043,Calendar!$A$2:$H$9997,8,FALSE),0) | G8043: =VLOOKUP(A8043,Calendar!$A$1:$H$9997,6,FALSE)-F8043 | H8043: 2 | I8043: 1
A8044: 46483 | B8044: Week | C8044: 4 | D8044: 2027 | E8044: 8 | F8044: =ROUND(((SUMIFS(Calendar!$F$2:$F$9997,Calendar!$B$2:$B$9997,D8044,Calendar!$C$2:$C$9997,C8044)*INDEX(ForeCalc!$B$37:$Y$274,MATCH(_xlfn.CONCAT(H8044," ",I8044),ForeCalc!$A$37:$A$274,0),MATCH(_xlfn.CONCAT(B8044," ",E8044),ForeCalc!$B$36:$Y$36,0))))*VLOOKUP(A8044,Calendar!$A$2:$H$9997,8,FALSE),0) | G8044: =VLOOKUP(A8044,Calendar!$A$1:$H$9997,6,FALSE)-F8044 | H8044: 2 | I8044: 1
A8045: 46484 | B8045: Week | C8045: 4 | D8045: 2027 | E8045: 8 | F8045: =ROUND(((SUMIFS(Calendar!$F$2:$F$9997,Calendar!$B$2:$B$9997,D8045,Calendar!$C$2:$C$9997,C8045)*INDEX(ForeCalc!$B$37:$Y$274,MATCH(_xlfn.CONCAT(H8045," ",I8045),ForeCalc!$A$37:$A$274,0),MATCH(_xlfn.CONCAT(B8045," ",E8045),ForeCalc!$B$36:$Y$36,0))))*VLOOKUP(A8045,Calendar!$A$2:$H$9997,8,FALSE),0) | G8045: =VLOOKUP(A8045,Calendar!$A$1:$H$9997,6,FALSE)-F8045 | H8045: 2 | I8045: 1
A8046: 46485 | B8046: Week | C8046: 4 | D8046: 2027 | E8046: 8 | F8046: =ROUND(((SUMIFS(Calendar!$F$2:$F$9997,Calendar!$B$2:$B$9997,D8046,Calendar!$C$2:$C$9997,C8046)*INDEX(ForeCalc!$B$37:$Y$274,MATCH(_xlfn.CONCAT(H8046," ",I8046),ForeCalc!$A$37:$A$274,0),MATCH(_xlfn.CONCAT(B8046," ",E8046),ForeCalc!$B$36:$Y$36,0))))*VLOOKUP(A8046,Calendar!$A$2:$H$9997,8,FALSE),0) | G8046: =VLOOKUP(A8046,Calendar!$A$1:$H$9997,6,FALSE)-F8046 | H8046: 2 | I8046: 1
... A8769: 47208 | B8769: Sat | C8769: 3 | D8769: 2029 | E8769: 8 | F8769: =ROUND(((SUMIFS(Calendar!$F$2:$F$9997,Calendar!$B$2:$B$9997,D8769,Calendar!$C$2:$C$9997,C8769)*INDEX(ForeCalc!$B$37:$Y$274,MATCH(_xlfn.CONCAT(H8769," ",I8769),ForeCalc!$A$37:$A$274,0),MATCH(_xlfn.CONCAT(B8769," ",E8769),ForeCalc!$B$36:$Y$36,0))))*VLOOKUP(A8769,Calendar!$A$2:$H$9997,8,FALSE),0) | G8769: =VLOOKUP(A8769,Calendar!$A$1:$H$9997,6,FALSE)-F8769 | H8769: 3 | I8769: 12

Sheet Calendar
A1: Date | B1: Year | C1: Month | D1: Day | E1: Type | F1: Avail Hours | G1: Staffed Hours | H1: Daily% of Month | I1: BusYr | J1: BusMnth | L1: Day | M1: Date | N1: Holiday | O1: Hours | P1: Available Hours
A2: 46113 | B2: 2026 | C2: 4 | D2: Wed | E2: Week | F2: =IF(ForeCalc!$F$1="Staffed Hours",G2,24) | G2: =IF(COUNTIF(M:M,Calendar!A2)>0,VLOOKUP(A2,M:P,4,FALSE),VLOOKUP(D2,BusData!$A$3:$D$10,4,FALSE)) | H2: =F2/SUMIFS($F$2:$F$9997,$B$2:$B$9997,B2,$C$2:$C$9997,C2) | I2: 1 | J2: 1 | L2: 46023 | M2: 46023 | N2: New Year's Day | O2: Closed | P2: 0
A3: 46114 | B3: 2026 | C3: 4 | D3: Thu | E3: Week | F3: =IF(ForeCalc!$F$1="Staffed Hours",G3,24) | G3: =IF(COUNTIF(M:M,Calendar!A3)>0,VLOOKUP(A3,M:P,4,FALSE),VLOOKUP(D3,BusData!$A$3:$D$10,4,FALSE)) | H3: =F3/SUMIFS($F$2:$F$9997,$B$2:$B$9997,B3,$C$2:$C$9997,C3) | I3: 1 | J3: 1 | L3: 46167 | M3: 46167 | N3: Memorial Day | O3: Closed | P3: 0
A4: 46115 | B4: 2026 | C4: 4 | D4: Fri | E4: Week | F4: =IF(ForeCalc!$F$1="Staffed Hours",G4,24) | G4: =IF(COUNTIF(M:M,Calendar!A4)>0,VLOOKUP(A4,M:P,4,FALSE),VLOOKUP(D4,BusData!$A$3:$D$10,4,FALSE)) | H4: =F4/SUMIFS($F$2:$F$9997,$B$2:$B$9997,B4,$C$2:$C$9997,C4) | I4: 1 | J4: 1 | L4: 46207 | M4: 46207 | N4: Independence Day | O4: Closed | P4: 0
A5: 46116 | B5: 2026 | C5: 4 | D5: Sat | E5: Sat | F5: =IF(ForeCalc!$F$1="Staffed Hours",G5,24) | G5: =IF(COUNTIF(M:M,Calendar!A5)>0,VLOOKUP(A5,M:P,4,FALSE),VLOOKUP(D5,BusData!$A$3:$D$10,4,FALSE)) | H5: =F5/SUMIFS($F$2:$F$9997,$B$2:$B$9997,B5,$C$2:$C$9997,C5) | I5: 1 | J5: 1 | L5: 46272 | M5: 46272 | N5: Labor Day | O5: Closed | P5: 0
A6: 46117 | B6: 2026 | C6: 4 | D6: Sun | E6: Sun | F6: =IF(ForeCalc!$F$1="Staffed Hours",G6,24) | G6: =IF(COUNTIF(M:M,Calendar!A6)>0,VLOOKUP(A6,M:P,4,FALSE),VLOOKUP(D6,BusData!$A$3:$D$10,4,FALSE)) | H6: =F6/SUMIFS($F$2:$F$9997,$B$2:$B$9997,B6,$C$2:$C$9997,C6) | I6: 1 | J6: 1 | L6: 46352 | M6: 46352 | N6: Thanksgiving | O6: Closed | P6: 0
A7: 46118 | B7: 2026 | C7: 4 | D7: Mon | E7: Week | F7: =IF(ForeCalc!$F$1="Staffed Hours",G7,24) | G7: =IF(COUNTIF(M:M,Calendar!A7)>0,VLOOKUP(A7,M:P,4,FALSE),VLOOKUP(D7,BusData!$A$3:$D$10,4,FALSE)) | H7: =F7/SUMIFS($F$2:$F$9997,$B$2:$B$9997,B7,$C$2:$C$9997,C7) | I7: 1 | J7: 1 | L7: 46380 | M7: 46380 | N7: Christmas Eve | O7: 6.00am - 4pm | P7: 10
A8: 46119 | B8: 2026 | C8: 4 | D8: Tue | E8: Week | F8: =IF(ForeCalc!$F$1="Staffed Hours",G8,24) | G8: =IF(COUNTIF(M:M,Calendar!A8)>0,VLOOKUP(A8,M:P,4,FALSE),VLOOKUP(D8,BusData!$A$3:$D$10,4,FALSE)) | H8: =F8/SUMIFS($F$2:$F$9997,$B$2:$B$9997,B8,$C$2:$C$9997,C8) | I8: 1 | J8: 1 | L8: 46381 | M8: 46381 | N8: Christmas Day | O8: Closed | P8: 0
A9: 46120 | B9: 2026 | C9: 4 | D9: Wed | E9: Week | F9: =IF(ForeCalc!$F$1="Staffed Hours",G9,24) | G9: =IF(COUNTIF(M:M,Calendar!A9)>0,VLOOKUP(A9,M:P,4,FALSE),VLOOKUP(D9,BusData!$A$3:$D$10,4,FALSE)) | H9: =F9/SUMIFS($F$2:$F$9997,$B$2:$B$9997,B9,$C$2:$C$9997,C9) | I9: 1 | J9: 1 | L9: 46387 | M9: 46387 | N9: New Year's Eve | O9: 6.00am - 4pm | P9: 10
A10: 46121 | B10: 2026 | C10: 4 | D10: Thu | E10: Week | F10: =IF(ForeCalc!$F$1="Staffed Hours",G10,24) | G10: =IF(COUNTIF(M:M,Calendar!A10)>0,VLOOKUP(A10,M:P,4,FALSE),VLOOKUP(D10,BusData!$A$3:$D$10,4,FALSE)) | H10: =F10/SUMIFS($F$2:$F$9997,$B$2:$B$9997,B10,$C$2:$C$9997,C10) | I10: 1 | J10: 1 | L10: 46388 | M10: 46388 | N10: New Year's Day | O10: Closed | P10: 0
A11: 46122 | B11: 2026 | C11: 4 | D11: Fri | E11: Week | F11: =IF(ForeCalc!$F$1="Staffed Hours",G11,24) | G11: =IF(COUNTIF(M:M,Calendar!A11)>0,VLOOKUP(A11,M:P,4,FALSE),VLOOKUP(D11,BusData!$A$3:$D$10,4,FALSE)) | H11: =F11/SUMIFS($F$2:$F$9997,$B$2:$B$9997,B11,$C$2:$C$9997,C11) | I11: 1 | J11: 1 | L11: 46538 | M11: 46538 | N11: Memorial Day | O11: Closed | P11: 0
A12: 46123 | B12: 2026 | C12: 4 | D12: Sat | E12: Sat | F12: =IF(ForeCalc!$F$1="Staffed Hours",G12,24) | G12: =IF(COUNTIF(M:M,Calendar!A12)>0,VLOOKUP(A12,M:P,4,FALSE),VLOOKUP(D12,BusData!$A$3:$D$10,4,FALSE)) | H12: =F12/SUMIFS($F$2:$F$9997,$B$2:$B$9997,B12,$C$2:$C$9997,C12) | I12: 1 | J12: 1 | L12: 46573 | M12: 46573 | N12: Independence Day | O12: Closed | P12: 0
A13: 46124 | B13: 2026 | C13: 4 | D13: Sun | E13: Sun | F13: =IF(ForeCalc!$F$1="Staffed Hours",G13,24) | G13: =IF(COUNTIF(M:M,Calendar!A13)>0,VLOOKUP(A13,M:P,4,FALSE),VLOOKUP(D13,BusData!$A$3:$D$10,4,FALSE)) | H13: =F13/SUMIFS($F$2:$F$9997,$B$2:$B$9997,B13,$C$2:$C$9997,C13) | I13: 1 | J13: 1 | L13: 46636 | M13: 46636 | N13: Labor Day | O13: Closed | P13: 0
... A26: 46137 | B26: 2026 | C26: 4 | D26: Sat | E26: Sat | F26: =IF(ForeCalc!$F$1="Staffed Hours",G26,24) | G26: =IF(COUNTIF(M:M,Calendar!A26)>0,VLOOKUP(A26,M:P,4,FALSE),VLOOKUP(D26,BusData!$A$3:$D$10,4,FALSE)) | H26: =F26/SUMIFS($F$2:$F$9997,$B$2:$B$9997,B26,$C$2:$C$9997,C26) | I26: 1 | J26: 1 | L26: 47119 | M26: 47119 | N26: New Year's Day | O26: Closed | P26: 0
A27: 46138 | B27: 2026 | C27: 4 | D27: Sun | E27: Sun | F27: =IF(ForeCalc!$F$1="Staffed Hours",G27,24) | G27: =IF(COUNTIF(M:M,Calendar!A27)>0,VLOOKUP(A27,M:P,4,FALSE),VLOOKUP(D27,BusData!$A$3:$D$10,4,FALSE)) | H27: =F27/SUMIFS($F$2:$F$9997,$B$2:$B$9997,B27,$C$2:$C$9997,C27) | I27: 1 | J27: 1
A28: 46139 | B28: 2026 | C28: 4 | D28: Mon | E28: Week | F28: =IF(ForeCalc!$F$1="Staffed Hours",G28,24) | G28: =IF(COUNTIF(M:M,Calendar!A28)>0,VLOOKUP(A28,M:P,4,FALSE),VLOOKUP(D28,BusData!$A$3:$D$10,4,FALSE)) | H28: =F28/SUMIFS($F$2:$F$9997,$B$2:$B$9997,B28,$C$2:$C$9997,C28) | I28: 1 | J28: 1
A29: 46140 | B29: 2026 | C29: 4 | D29: Tue | E29: Week | F29: =IF(ForeCalc!$F$1="Staffed Hours",G29,24) | G29: =IF(COUNTIF(M:M,Calendar!A29)>0,VLOOKUP(A29,M:P,4,FALSE),VLOOKUP(D29,BusData!$A$3:$D$10,4,FALSE)) | H29: =F29/SUMIFS($F$2:$F$9997,$B$2:$B$9997,B29,$C$2:$C$9997,C29) | I29: 1 | J29: 1
A30: 46141 | B30: 2026 | C30: 4 | D30: Wed | E30: Week | F30: =IF(ForeCalc!$F$1="Staffed Hours",G30,24) | G30: =IF(COUNTIF(M:M,Calendar!A30)>0,VLOOKUP(A30,M:P,4,FALSE),VLOOKUP(D30,BusData!$A$3:$D$10,4,FALSE)) | H30: =F30/SUMIFS($F$2:$F$9997,$B$2:$B$9997,B30,$C$2:$C$9997,C30) | I30: 1 | J30: 1
A31: 46142 | B31: 2026 | C31: 4 | D31: Thu | E31: Week | F31: =IF(ForeCalc!$F$1="Staffed Hours",G31,24) | G31: =IF(COUNTIF(M:M,Calendar!A31)>0,VLOOKUP(A31,M:P,4,FALSE),VLOOKUP(D31,BusData!$A$3:$D$10,4,FALSE)) | H31: =F31/SUMIFS($F$2:$F$9997,$B$2:$B$9997,B31,$C$2:$C$9997,C31) | I31: 1 | J31: 1
A32: 46143 | B32: 2026 | C32: 5 | D32: Fri | E32: Week | F32: =IF(ForeCalc!$F$1="Staffed Hours",G32,24) | G32: =IF(COUNTIF(M:M,Calendar!A32)>0,VLOOKUP(A32,M:P,4,FALSE),VLOOKUP(D32,BusData!$A$3:$D$10,4,FALSE)) | H32: =F32/SUMIFS($F$2:$F$9997,$B$2:$B$9997,B32,$C$2:$C$9997,C32) | I32: 1 | J32: 2
A33: 46144 | B33: 2026 | C33: 5 | D33: Sat | E33: Sat | F33: =IF(ForeCalc!$F$1="Staffed Hours",G33,24) | G33: =IF(COUNTIF(M:M,Calendar!A33)>0,VLOOKUP(A33,M:P,4,FALSE),VLOOKUP(D33,BusData!$A$3:$D$10,4,FALSE)) | H33: =F33/SUMIFS($F$2:$F$9997,$B$2:$B$9997,B33,$C$2:$C$9997,C33) | I33: 1 | J33: 2
A34: 46145 | B34: 2026 | C34: 5 | D34: Sun | E34: Sun | F34: =IF(ForeCalc!$F$1="Staffed Hours",G34,24) | G34: =IF(COUNTIF(M:M,Calendar!A34)>0,VLOOKUP(A34,M:P,4,FALSE),VLOOKUP(D34,BusData!$A$3:$D$10,4,FALSE)) | H34: =F34/SUMIFS($F$2:$F$9997,$B$2:$B$9997,B34,$C$2:$C$9997,C34) | I34: 1 | J34: 2
A35: 46146 | B35: 2026 | C35: 5 | D35: Mon | E35: Week | F35: =IF(ForeCalc!$F$1="Staffed Hours",G35,24) | G35: =IF(COUNTIF(M:M,Calendar!A35)>0,VLOOKUP(A35,M:P,4,FALSE),VLOOKUP(D35,BusData!$A$3:$D$10,4,FALSE)) | H35: =F35/SUMIFS($F$2:$F$9997,$B$2:$B$9997,B35,$C$2:$C$9997,C35) | I35: 1 | J35: 2
A36: 46147 | B36: 2026 | C36: 5 | D36: Tue | E36: Week | F36: =IF(ForeCalc!$F$1="Staffed Hours",G36,24) | G36: =IF(COUNTIF(M:M,Calendar!A36)>0,VLOOKUP(A36,M:P,4,FALSE),VLOOKUP(D36,BusData!$A$3:$D$10,4,FALSE)) | H36: =F36/SUMIFS($F$2:$F$9997,$B$2:$B$9997,B36,$C$2:$C$9997,C36) | I36: 1 | J36: 2
A37: 46148 | B37: 2026 | C37: 5 | D37: Wed | E37: Week | F37: =IF(ForeCalc!$F$1="Staffed Hours",G37,24) | G37: =IF(COUNTIF(M:M,Calendar!A37)>0,VLOOKUP(A37,M:P,4,FALSE),VLOOKUP(D37,BusData!$A$3:$D$10,4,FALSE)) | H37: =F37/SUMIFS($F$2:$F$9997,$B$2:$B$9997,B37,$C$2:$C$9997,C37) | I37: 1 | J37: 2
A38: 46149 | B38: 2026 | C38: 5 | D38: Thu | E38: Week | F38: =IF(ForeCalc!$F$1="Staffed Hours",G38,24) | G38: =IF(COUNTIF(M:M,Calendar!A38)>0,VLOOKUP(A38,M:P,4,FALSE),VLOOKUP(D38,BusData!$A$3:$D$10,4,FALSE)) | H38: =F38/SUMIFS($F$2:$F$9997,$B$2:$B$9997,B38,$C$2:$C$9997,C38) | I38: 1 | J38: 2
... A1097: 47208 | B1097: 2029 | C1097: 3 | D1097: Sat | E1097: Sat | F1097: =IF(ForeCalc!$F$1="Staffed Hours",G1097,24) | G1097: =IF(COUNTIF(M:M,Calendar!A1097)>0,VLOOKUP(A1097,M:P,4,FALSE),VLOOKUP(D1097,BusData!$A$3:$D$10,4,FALSE)) | H1097: =F1097/SUMIFS($F$2:$F$9997,$B$2:$B$9997,B1097,$C$2:$C$9997,C1097) | I1097: 3 | J1097: 12

Sheet BusData
A1: Business Data
A2: Staffed Hours
A3: Day | B3: From (24hr) | C3: To (24hr) | D3: Available Hours
A4: Mon | B4: 8 | C4: 22 | D4: =C4-B4
A5: Tue | B5: 8 | C5: 22 | D5: =C5-B5
A6: Wed | B6: 8 | C6: 22 | D6: =C6-B6
A7: Thu | B7: 8 | C7: 22 | D7: =C7-B7
A8: Fri | B8: 8 | C8: 22 | D8: =C8-B8
A9: Sat | B9: 9 | C9: 17 | D9: =C9-B9
A10: Sun | B10: 9 | C10: 16 | D10: =C10-B10
A12: Pod Details
A13: Room Number | B13: 8
A15: Business Years
A16: Years | B16: Date
A17: 1 | B17: 46113
A18: 2 | B18: 46478
A19: 3 | B19: 46844

Sheet ForeCalc
A1: Forecast Calculator | E1: Current Scenario: | F1: Open 24 hrs | H1: *Forecast creator (used to generate attendance scenarios) removed from this sample data set *Staffed Hours scenarios, also removed
A3: Opening Month - Day Forecast (Weekday) | J3: Opening Month - Day Forecast (Sat) | R3: Opening Month - Day Forecast (Sun)
A4: Hour | B4: 1 | C4: 2 | D4: 3 | E4: 4 | F4: 5 | G4: 6 | H4: 7 | I4: 8 | J4: 1 | K4: 2 | L4: 3 | M4: 4 | N4: 5 | O4: 6 | P4: 7 | Q4: 8 | R4: 1 | S4: 2 | T4: 3 | U4: 4 | V4: 5 | W4: 6 | X4: 7 | Y4: 8
A5: 0 | B5: 0 | C5: 0 | D5: 0 | E5: 0 | F5: 0 | G5: 0 | H5: 0 | I5: 0 | J5: 0 | K5: 0 | L5: 1 | M5: 0 | N5: 0 | O5: 0 | P5: 1 | Q5: 0 | R5: 0 | S5: 0 | T5: 0 | U5: 0 | V5: 0 | W5: 1 | X5: 1 | Y5: 1
A6: 1 | B6: 0 | C6: 0 | D6: 0 | E6: 0 | F6: 0 | G6: 1 | H6: 0 | I6: 1 | J6: 0 | K6: 0 | L6: 0 | M6: 0 | N6: 0 | O6: 0 | P6: 0 | Q6: 0 | R6: 0 | S6: 1 | T6: 0 | U6: 1 | V6: 0 | W6: 0 | X6: 0 | Y6: 0
A7: 2 | B7: 0 | C7: 0 | D7: 0 | E7: 0 | F7: 0 | G7: 0 | H7: 0 | I7: 0 | J7: 1 | K7: 1 | L7: 0 | M7: 0 | N7: 1 | O7: 0 | P7: 0 | Q7: 0 | R7: 0 | S7: 0 | T7: 0 | U7: 0 | V7: 0 | W7: 0 | X7: 1 | Y7: 0
A8: 3 | B8: 0 | C8: 0 | D8: 0 | E8: 0 | F8: 0 | G8: 0 | H8: 0 | I8: 0 | J8: 0 | K8: 1 | L8: 0 | M8: 0 | N8: 0 | O8: 1 | P8: 0 | Q8: 1 | R8: 0 | S8: 0 | T8: 0 | U8: 0 | V8: 0 | W8: 1 | X8: 0 | Y8: 0
A9: 4 | B9: 1 | C9: 0 | D9: 0 | E9: 0 | F9: 0 | G9: 0 | H9: 0 | I9: 1 | J9: 1 | K9: 0 | L9: 0 | M9: 0 | N9: 0 | O9: 0 | P9: 0 | Q9: 0 | R9: 0 | S9: 0 | T9: 0 | U9: 1 | V9: 0 | W9: 0 | X9: 0 | Y9: 1
A10: 5 | B10: 0 | C10: 1 | D10: 0 | E10: 1 | F10: 0 | G10: 0 | H10: 0 | I10: 0 | J10: 0 | K10: 0 | L10: 1 | M10: 0 | N10: 1 | O10: 0 | P10: 1 | Q10: 0 | R10: 0 | S10: 0 | T10: 0 | U10: 0 | V10: 0 | W10: 0 | X10: 0 | Y10: 1
A11: 6 | B11: 0 | C11: 0 | D11: 0 | E11: 0 | F11: 0 | G11: 0 | H11: 0 | I11: 0 | J11: 1 | K11: 0 | L11: 0 | M11: 0 | N11: 0 | O11: 0 | P11: 0 | Q11: 0 | R11: 0 | S11: 0 | T11: 0 | U11: 1 | V11: 1 | W11: 0 | X11: 0 | Y11: 1
A12: 7 | B12: 0 | C12: 0 | D12: 0 | E12: 0 | F12: 1 | G12: 0 | H12: 0 | I12: 0 | J12: 1 | K12: 0 | L12: 0 | M12: 0 | N12: 0 | O12: 1 | P12: 0 | Q12: 0 | R12: 1 | S12: 1 | T12: 0 | U12: 0 | V12: 0 | W12: 1 | X12: 1 | Y12: 1
A13: 8 | B13: 1 | C13: 1 | D13: 1 | E13: 0 | F13: 0 | G13: 0 | H13: 0 | I13: 0 | J13: 0 | K13: 0 | L13: 0 | M13: 1 | N13: 0 | O13: 0 | P13: 0 | Q13: 0 | R13: 0 | S13: 0 | T13: 0 | U13: 0 | V13: 0 | W13: 1 | X13: 0 | Y13: 0
A14: 9 | B14: 0 | C14: 0 | D14: 0 | E14: 0 | F14: 0 | G14: 0 | H14: 1 | I14: 1 | J14: 1 | K14: 1 | L14: 0 | M14: 0 | N14: 0 | O14: 0 | P14: 1 | Q14: 0 | R14: 0 | S14: 0 | T14: 0 | U14: 0 | V14: 0 | W14: 0 | X14: 0 | Y14: 0
A15: 10 | B15: 0 | C15: 1 | D15: 0 | E15: 0 | F15: 0 | G15: 0 | H15: 0 | I15: 1 | J15: 0 | K15: 1 | L15: 0 | M15: 0 | N15: 0 | O15: 0 | P15: 0 | Q15: 0 | R15: 1 | S15: 1 | T15: 1 | U15: 1 | V15: 0 | W15: 0 | X15: 0 | Y15: 0
A16: 11 | B16: 1 | C16: 0 | D16: 1 | E16: 1 | F16: 0 | G16: 0 | H16: 0 | I16: 0 | J16: 1 | K16: 0 | L16: 0 | M16: 0 | N16: 0 | O16: 0 | P16: 0 | Q16: 0 | R16: 1 | S16: 0 | T16: 1 | U16: 0 | V16: 0 | W16: 0 | X16: 1 | Y16: 0
... A28: 23 | B28: 0 | C28: 0 | D28: 0 | E28: 0 | F28: 0 | G28: 0 | H28: 0 | I28: 0 | J28: 0 | K28: 0 | L28: 0 | M28: 0 | N28: 0 | O28: 0 | P28: 1 | Q28: 0 | R28: 0 | S28: 0 | T28: 0 | U28: 0 | V28: 0 | W28: 0 | X28: 0 | Y28: 0
A29: Avail | B29: 24 | C29: 24 | D29: 24 | E29: 24 | F29: 24 | G29: 24 | H29: 24 | I29: 24 | J29: 24 | K29: 24 | L29: 24 | M29: 24 | N29: 24 | O29: 24 | P29: 24 | Q29: 24 | R29: 24 | S29: 24 | T29: 24 | U29: 24 | V29: 24 | W29: 24 | X29: 24 | Y29: 24
A30: Used | B30: 6 | C30: 6 | D30: 7 | E30: 7 | F30: 4 | G30: 2 | H30: 5 | I30: 8 | J30: 9 | K30: 7 | L30: 6 | M30: 4 | N30: 4 | O30: 6 | P30: 9 | Q30: 3 | R30: 9 | S30: 6 | T30: 4 | U30: 6 | V30: 4 | W30: 4 | X30: 7 | Y30: 7
A31: Opening Month - Day Forecast (Combined)
B32: 1 | C32: 2 | D32: 3 | E32: 4 | F32: 5 | G32: 6 | H32: 7 | I32: 8 | J32: 1 | K32: 2 | L32: 3 | M32: 4 | N32: 5 | O32: 6 | P32: 7 | Q32: 8 | R32: 1 | S32: 2 | T32: 3 | U32: 4 | V32: 5 | W32: 6 | X32: 7 | Y32: 8 | Z32: Weekday | AA32: Sat | AB32: Sun | AC32: Tot
B33: =B30/B29 | C33: =C30/C29 | D33: =D30/D29 | E33: =E30/E29 | F33: =F30/F29 | G33: =G30/G29 | H33: =H30/H29 | I33: =I30/I29 | ... Y33: =Y30/Y29 | Z33: =SUM(B30:I30) | AA33: =SUM(J30:Q30) | AB33: =SUM(R30:Y30) | AC33: =SUM(Z33:AB33)
B35: Daytype & Room | J35: Daytype & Room | R35: Daytype & Room
A36: Bus Year/Month | B36: Week 1 | C36: Week 2 | D36: Week 3 | E36: Week 4 | F36: Week 5 | G36: Week 6 | H36: Week 7 | I36: Week 8 | J36: Sat 1 | K36: Sat 2 | L36: Sat 3 | M36: Sat 4 | N36: Sat 5 | O36: Sat 6 | P36: Sat 7 | Q36: Sat 8 | R36: Sun 1 | S36: Sun 2 | T36: Sun 3 | U36: Sun 4 | V36: Sun 5 | W36: Sun 6 | X36: Sun 7 | Y36: Sun 8 | Z36: %i/d | AA36: Year Increase %
A37: 1 1 | B37: =B33 | C37: =C33 | D37: =D33 | E37: =E33 | F37: =F33 | G37: =G33 | H37: =H33 | I37: =I33 | ... Y37: =Y33 | AA37: 2027 | AB37: 0.05
A38: 1 2 | B38: =B37+$Z38 | C38: =C37+$Z38 | D38: =D37+$Z38 | E38: =E37+$Z38 | F38: =F37+$Z38 | G38: =G37+$Z38 | H38: =H37+$Z38 | I38: =I37+$Z38 | ... Y38: =Y37+$Z38 | Z38: 0.01 | AA38: 2028 | AB38: 0.03
A39: 1 3 | B39: =B38+$Z39 | C39: =C38+$Z39 | D39: =D38+$Z39 | E39: =E38+$Z39 | F39: =F38+$Z39 | G39: =G38+$Z39 | H39: =H38+$Z39 | I39: =I38+$Z39 | ... Y39: =Y38+$Z39 | Z39: 0.01
A40: 1 4 | B40: =B39+$Z40 | C40: =C39+$Z40 | D40: =D39+$Z40 | E40: =E39+$Z40 | F40: =F39+$Z40 | G40: =G39+$Z40 | H40: =H39+$Z40 | I40: =I39+$Z40 | ... Y40: =Y39+$Z40 | Z40: 0
A41: 1 5 | B41: =B40+$Z41 | C41: =C40+$Z41 | D41: =D40+$Z41 | E41: =E40+$Z41 | F41: =F40+$Z41 | G41: =G40+$Z41 | H41: =H40+$Z41 | I41: =I40+$Z41 | ... Y41: =Y40+$Z41 | Z41: 0
A42: 1 6 | B42: =B41+$Z42 | C42: =C41+$Z42 | D42: =D41+$Z42 | E42: =E41+$Z42 | F42: =F41+$Z42 | G42: =G41+$Z42 | H42: =H41+$Z42 | I42: =I41+$Z42 | ... Y42: =Y41+$Z42 | Z42: 0.01
A43: 1 7 | B43: =B42+$Z43 | C43: =C42+$Z43 | D43: =D42+$Z43 | E43: =E42+$Z43 | F43: =F42+$Z43 | G43: =G42+$Z43 | H43: =H42+$Z43 | I43: =I42+$Z43 | ... Y43: =Y42+$Z43 | Z43: 0.02
A44: 1 8 | B44: =B43+$Z44 | C44: =C43+$Z44 | D44: =D43+$Z44 | E44: =E43+$Z44 | F44: =F43+$Z44 | G44: =G43+$Z44 | H44: =H43+$Z44 | I44: =I43+$Z44 | ... Y44: =Y43+$Z44 | Z44: 0.01
A45: 1 9 | B45: =B44+$Z45 | C45: =C44+$Z45 | D45: =D44+$Z45 | E45: =E44+$Z45 | F45: =F44+$Z45 | G45: =G44+$Z45 | H45: =H44+$Z45 | I45: =I44+$Z45 | ... Y45: =Y44+$Z45 | Z45: 0
A46: 1 10 | B46: =B45+$Z46 | C46: =C45+$Z46 | D46: =D45+$Z46 | E46: =E45+$Z46 | F46: =F45+$Z46 | G46: =G45+$Z46 | H46: =H45+$Z46 | I46: =I45+$Z46 | ... Y46: =Y45+$Z46 | Z46: -0.01
A47: 1 11 | B47: =B46+$Z47 | C47: =C46+$Z47 | D47: =D46+$Z47 | E47: =E46+$Z47 | F47: =F46+$Z47 | G47: =G46+$Z47 | H47: =H46+$Z47 | I47: =I46+$Z47 | ... Y47: =Y46+$Z47 | Z47: 0
A48: 1 12 | B48: =B47+$Z48 | C48: =C47+$Z48 | D48: =D47+$Z48 | E48: =E47+$Z48 | F48: =F47+$Z48 | G48: =G47+$Z48 | H48: =H47+$Z48 | I48: =I47+$Z48 | ... Y48: =Y47+$Z48 | Z48: -0.01
A49: 2 1 | B49: =B37+$AB$37 | C49: =C37+$AB$37 | D49: =D37+$AB$37 | E49: =E37+$AB$37 | F49: =F37+$AB$37 | G49: =G37+$AB$37 | H49: =H37+$AB$37 | I49: =I37+$AB$37 | ... Y49: =Y37+$AB$37
A50: 2 2 | B50: =B38+$AB$37 | C50: =C38+$AB$37 | D50: =D38+$AB$37 | E50: =E38+$AB$37 | F50: =F38+$AB$37 | G50: =G38+$AB$37 | H50: =H38+$AB$37 | I50: =I38+$AB$37 | ... Y50: =Y38+$AB$37
A51: 2 3 | B51: =B39+$AB$37 | C51: =C39+$AB$37 | D51: =D39+$AB$37 | E51: =E39+$AB$37 | F51: =F39+$AB$37 | G51: =G39+$AB$37 | H51: =H39+$AB$37 | I51: =I39+$AB$37 | ... Y51: =Y39+$AB$37
A52: 2 4 | B52: =B40+$AB$37 | C52: =C40+$AB$37 | D52: =D40+$AB$37 | E52: =E40+$AB$37 | F52: =F40+$AB$37 | G52: =G40+$AB$37 | H52: =H40+$AB$37 | I52: =I40+$AB$37 | ... Y52: =Y40+$AB$37
A53: 2 5 | B53: =B41+$AB$37 | C53: =C41+$AB$37 | D53: =D41+$AB$37 | E53: =E41+$AB$37 | F53: =F41+$AB$37 | G53: =G41+$AB$37 | H53: =H41+$AB$37 | I53: =I41+$AB$37 | ... Y53: =Y41+$AB$37
...
